[2022-01-25 19:36:58,815] {taskinstance.py:1032} INFO - Dependencies all met for <TaskInstance: ingest_data.extract_all_data manual__2022-01-25T19:36:54.952812+00:00 [queued]>
[2022-01-25 19:36:58,840] {taskinstance.py:1032} INFO - Dependencies all met for <TaskInstance: ingest_data.extract_all_data manual__2022-01-25T19:36:54.952812+00:00 [queued]>
[2022-01-25 19:36:58,840] {taskinstance.py:1238} INFO - 
--------------------------------------------------------------------------------
[2022-01-25 19:36:58,840] {taskinstance.py:1239} INFO - Starting attempt 1 of 1
[2022-01-25 19:36:58,841] {taskinstance.py:1240} INFO - 
--------------------------------------------------------------------------------
[2022-01-25 19:36:58,877] {taskinstance.py:1259} INFO - Executing <Task(BashOperator): extract_all_data> on 2022-01-25 19:36:54.952812+00:00
[2022-01-25 19:36:58,896] {standard_task_runner.py:76} INFO - Running: ['***', 'tasks', 'run', 'ingest_data', 'extract_all_data', 'manual__2022-01-25T19:36:54.952812+00:00', '--job-id', '101', '--raw', '--subdir', 'DAGS_FOLDER/dag_01.py', '--cfg-path', '/tmp/tmpmn1rvkdt', '--error-file', '/tmp/tmpnne50z4m']
[2022-01-25 19:36:58,898] {standard_task_runner.py:77} INFO - Job 101: Subtask extract_all_data
[2022-01-25 19:36:58,888] {standard_task_runner.py:52} INFO - Started process 3710 to run task
[2022-01-25 19:36:59,010] {logging_mixin.py:109} INFO - Running <TaskInstance: ingest_data.extract_all_data manual__2022-01-25T19:36:54.952812+00:00 [running]> on host 223810fcea28
[2022-01-25 19:36:59,139] {taskinstance.py:1426} INFO - Exporting the following env vars:
AIRFLOW_CTX_DAG_OWNER=***
AIRFLOW_CTX_DAG_ID=ingest_data
AIRFLOW_CTX_TASK_ID=extract_all_data
AIRFLOW_CTX_EXECUTION_DATE=2022-01-25T19:36:54.952812+00:00
AIRFLOW_CTX_DAG_RUN_ID=manual__2022-01-25T19:36:54.952812+00:00
[2022-01-25 19:36:59,140] {subprocess.py:62} INFO - Tmp dir root location: 
 /tmp
[2022-01-25 19:36:59,141] {subprocess.py:74} INFO - Running command: ['bash', '-c', 'cd /opt/***/ && echo ----------------------EMPIEZA----------------- && pwd && python ./functions/extract.py']
[2022-01-25 19:36:59,165] {subprocess.py:85} INFO - Output:
[2022-01-25 19:36:59,165] {subprocess.py:89} INFO - ----------------------EMPIEZA-----------------
[2022-01-25 19:36:59,166] {subprocess.py:89} INFO - /opt/***
[2022-01-25 19:36:59,437] {subprocess.py:89} INFO - python: can't open file './functions/extract.py': [Errno 2] No such file or directory
[2022-01-25 19:36:59,440] {subprocess.py:93} INFO - Command exited with return code 2
[2022-01-25 19:36:59,468] {taskinstance.py:1700} ERROR - Task failed with exception
Traceback (most recent call last):
  File "/home/airflow/.local/lib/python3.6/site-packages/airflow/models/taskinstance.py", line 1329, in _run_raw_task
    self._execute_task_with_callbacks(context)
  File "/home/airflow/.local/lib/python3.6/site-packages/airflow/models/taskinstance.py", line 1455, in _execute_task_with_callbacks
    result = self._execute_task(context, self.task)
  File "/home/airflow/.local/lib/python3.6/site-packages/airflow/models/taskinstance.py", line 1511, in _execute_task
    result = execute_callable(context=context)
  File "/home/airflow/.local/lib/python3.6/site-packages/airflow/operators/bash.py", line 188, in execute
    f'Bash command failed. The command returned a non-zero exit code {result.exit_code}.'
airflow.exceptions.AirflowException: Bash command failed. The command returned a non-zero exit code 2.
[2022-01-25 19:36:59,485] {taskinstance.py:1277} INFO - Marking task as FAILED. dag_id=ingest_data, task_id=extract_all_data, execution_date=20220125T193654, start_date=20220125T193658, end_date=20220125T193659
[2022-01-25 19:36:59,508] {standard_task_runner.py:92} ERROR - Failed to execute job 101 for task extract_all_data
Traceback (most recent call last):
  File "/home/airflow/.local/lib/python3.6/site-packages/airflow/task/task_runner/standard_task_runner.py", line 85, in _start_by_fork
    args.func(args, dag=self.dag)
  File "/home/airflow/.local/lib/python3.6/site-packages/airflow/cli/cli_parser.py", line 48, in command
    return func(*args, **kwargs)
  File "/home/airflow/.local/lib/python3.6/site-packages/airflow/utils/cli.py", line 92, in wrapper
    return f(*args, **kwargs)
  File "/home/airflow/.local/lib/python3.6/site-packages/airflow/cli/commands/task_command.py", line 298, in task_run
    _run_task_by_selected_method(args, dag, ti)
  File "/home/airflow/.local/lib/python3.6/site-packages/airflow/cli/commands/task_command.py", line 107, in _run_task_by_selected_method
    _run_raw_task(args, ti)
  File "/home/airflow/.local/lib/python3.6/site-packages/airflow/cli/commands/task_command.py", line 184, in _run_raw_task
    error_file=args.error_file,
  File "/home/airflow/.local/lib/python3.6/site-packages/airflow/utils/session.py", line 70, in wrapper
    return func(*args, session=session, **kwargs)
  File "/home/airflow/.local/lib/python3.6/site-packages/airflow/models/taskinstance.py", line 1329, in _run_raw_task
    self._execute_task_with_callbacks(context)
  File "/home/airflow/.local/lib/python3.6/site-packages/airflow/models/taskinstance.py", line 1455, in _execute_task_with_callbacks
    result = self._execute_task(context, self.task)
  File "/home/airflow/.local/lib/python3.6/site-packages/airflow/models/taskinstance.py", line 1511, in _execute_task
    result = execute_callable(context=context)
  File "/home/airflow/.local/lib/python3.6/site-packages/airflow/operators/bash.py", line 188, in execute
    f'Bash command failed. The command returned a non-zero exit code {result.exit_code}.'
airflow.exceptions.AirflowException: Bash command failed. The command returned a non-zero exit code 2.
[2022-01-25 19:36:59,529] {local_task_job.py:154} INFO - Task exited with return code 1
[2022-01-25 19:36:59,592] {local_task_job.py:264} INFO - 0 downstream tasks scheduled from follow-on schedule check
