[2022-01-25 18:07:01,590] {taskinstance.py:1032} INFO - Dependencies all met for <TaskInstance: ingest_data.create_venv manual__2022-01-25T18:07:00.165152+00:00 [queued]>
[2022-01-25 18:07:01,612] {taskinstance.py:1032} INFO - Dependencies all met for <TaskInstance: ingest_data.create_venv manual__2022-01-25T18:07:00.165152+00:00 [queued]>
[2022-01-25 18:07:01,612] {taskinstance.py:1238} INFO - 
--------------------------------------------------------------------------------
[2022-01-25 18:07:01,612] {taskinstance.py:1239} INFO - Starting attempt 1 of 1
[2022-01-25 18:07:01,612] {taskinstance.py:1240} INFO - 
--------------------------------------------------------------------------------
[2022-01-25 18:07:01,661] {taskinstance.py:1259} INFO - Executing <Task(BashOperator): create_venv> on 2022-01-25 18:07:00.165152+00:00
[2022-01-25 18:07:01,668] {standard_task_runner.py:52} INFO - Started process 7508 to run task
[2022-01-25 18:07:01,675] {standard_task_runner.py:76} INFO - Running: ['***', 'tasks', 'run', 'ingest_data', 'create_venv', 'manual__2022-01-25T18:07:00.165152+00:00', '--job-id', '12', '--raw', '--subdir', 'DAGS_FOLDER/dag_01.py', '--cfg-path', '/tmp/tmpgxuo_4h6', '--error-file', '/tmp/tmp6irbvfsa']
[2022-01-25 18:07:01,676] {standard_task_runner.py:77} INFO - Job 12: Subtask create_venv
[2022-01-25 18:07:01,861] {logging_mixin.py:109} INFO - Running <TaskInstance: ingest_data.create_venv manual__2022-01-25T18:07:00.165152+00:00 [running]> on host 1aa77c892e3a
[2022-01-25 18:07:02,033] {taskinstance.py:1426} INFO - Exporting the following env vars:
AIRFLOW_CTX_DAG_OWNER=***
AIRFLOW_CTX_DAG_ID=ingest_data
AIRFLOW_CTX_TASK_ID=create_venv
AIRFLOW_CTX_EXECUTION_DATE=2022-01-25T18:07:00.165152+00:00
AIRFLOW_CTX_DAG_RUN_ID=manual__2022-01-25T18:07:00.165152+00:00
[2022-01-25 18:07:02,035] {subprocess.py:62} INFO - Tmp dir root location: 
 /tmp
[2022-01-25 18:07:02,036] {subprocess.py:74} INFO - Running command: ['bash', '-c', 'virtualenv venv && source venv/bin/activate  && pip install -r requirements.txt']
[2022-01-25 18:07:02,047] {subprocess.py:85} INFO - Output:
[2022-01-25 18:07:03,683] {subprocess.py:89} INFO - created virtual environment CPython3.6.15.final.0-64 in 633ms
[2022-01-25 18:07:03,683] {subprocess.py:89} INFO -   creator CPython3Posix(dest=/tmp/***tmpqshcojtt/venv, clear=False, no_vcs_ignore=False, global=False)
[2022-01-25 18:07:03,683] {subprocess.py:89} INFO -   seeder FromAppData(download=False, pip=bundle, setuptools=bundle, wheel=bundle, via=copy, app_data_dir=/home/***/.local/share/virtualenv)
[2022-01-25 18:07:03,683] {subprocess.py:89} INFO -     added seed packages: pip==21.3.1, setuptools==58.3.0, wheel==0.37.0
[2022-01-25 18:07:03,683] {subprocess.py:89} INFO -   activators BashActivator,CShellActivator,FishActivator,NushellActivator,PowerShellActivator,PythonActivator
[2022-01-25 18:07:06,904] {subprocess.py:89} INFO - ERROR: Could not open requirements file: [Errno 2] No such file or directory: 'requirements.txt'
[2022-01-25 18:07:07,884] {subprocess.py:93} INFO - Command exited with return code 1
[2022-01-25 18:07:07,953] {taskinstance.py:1700} ERROR - Task failed with exception
Traceback (most recent call last):
  File "/home/airflow/.local/lib/python3.6/site-packages/airflow/models/taskinstance.py", line 1329, in _run_raw_task
    self._execute_task_with_callbacks(context)
  File "/home/airflow/.local/lib/python3.6/site-packages/airflow/models/taskinstance.py", line 1455, in _execute_task_with_callbacks
    result = self._execute_task(context, self.task)
  File "/home/airflow/.local/lib/python3.6/site-packages/airflow/models/taskinstance.py", line 1511, in _execute_task
    result = execute_callable(context=context)
  File "/home/airflow/.local/lib/python3.6/site-packages/airflow/operators/bash.py", line 188, in execute
    f'Bash command failed. The command returned a non-zero exit code {result.exit_code}.'
airflow.exceptions.AirflowException: Bash command failed. The command returned a non-zero exit code 1.
[2022-01-25 18:07:07,964] {taskinstance.py:1277} INFO - Marking task as FAILED. dag_id=ingest_data, task_id=create_venv, execution_date=20220125T180700, start_date=20220125T180701, end_date=20220125T180707
[2022-01-25 18:07:07,989] {standard_task_runner.py:92} ERROR - Failed to execute job 12 for task create_venv
Traceback (most recent call last):
  File "/home/airflow/.local/lib/python3.6/site-packages/airflow/task/task_runner/standard_task_runner.py", line 85, in _start_by_fork
    args.func(args, dag=self.dag)
  File "/home/airflow/.local/lib/python3.6/site-packages/airflow/cli/cli_parser.py", line 48, in command
    return func(*args, **kwargs)
  File "/home/airflow/.local/lib/python3.6/site-packages/airflow/utils/cli.py", line 92, in wrapper
    return f(*args, **kwargs)
  File "/home/airflow/.local/lib/python3.6/site-packages/airflow/cli/commands/task_command.py", line 298, in task_run
    _run_task_by_selected_method(args, dag, ti)
  File "/home/airflow/.local/lib/python3.6/site-packages/airflow/cli/commands/task_command.py", line 107, in _run_task_by_selected_method
    _run_raw_task(args, ti)
  File "/home/airflow/.local/lib/python3.6/site-packages/airflow/cli/commands/task_command.py", line 184, in _run_raw_task
    error_file=args.error_file,
  File "/home/airflow/.local/lib/python3.6/site-packages/airflow/utils/session.py", line 70, in wrapper
    return func(*args, session=session, **kwargs)
  File "/home/airflow/.local/lib/python3.6/site-packages/airflow/models/taskinstance.py", line 1329, in _run_raw_task
    self._execute_task_with_callbacks(context)
  File "/home/airflow/.local/lib/python3.6/site-packages/airflow/models/taskinstance.py", line 1455, in _execute_task_with_callbacks
    result = self._execute_task(context, self.task)
  File "/home/airflow/.local/lib/python3.6/site-packages/airflow/models/taskinstance.py", line 1511, in _execute_task
    result = execute_callable(context=context)
  File "/home/airflow/.local/lib/python3.6/site-packages/airflow/operators/bash.py", line 188, in execute
    f'Bash command failed. The command returned a non-zero exit code {result.exit_code}.'
airflow.exceptions.AirflowException: Bash command failed. The command returned a non-zero exit code 1.
[2022-01-25 18:07:08,030] {local_task_job.py:154} INFO - Task exited with return code 1
[2022-01-25 18:07:08,071] {dagrun.py:628} WARNING - Failed to get task '<TaskInstance: ingest_data.load_venv manual__2022-01-25T18:07:00.165152+00:00 [None]>' for dag 'ingest_data'. Marking it as removed.
[2022-01-25 18:07:08,095] {local_task_job.py:264} INFO - 0 downstream tasks scheduled from follow-on schedule check
