[2022-01-25 19:25:37,906] {taskinstance.py:1032} INFO - Dependencies all met for <TaskInstance: ingest_data.extract_all_dataa manual__2022-01-25T19:25:35.038530+00:00 [queued]>
[2022-01-25 19:25:37,949] {taskinstance.py:1032} INFO - Dependencies all met for <TaskInstance: ingest_data.extract_all_dataa manual__2022-01-25T19:25:35.038530+00:00 [queued]>
[2022-01-25 19:25:37,949] {taskinstance.py:1238} INFO - 
--------------------------------------------------------------------------------
[2022-01-25 19:25:37,950] {taskinstance.py:1239} INFO - Starting attempt 1 of 1
[2022-01-25 19:25:37,950] {taskinstance.py:1240} INFO - 
--------------------------------------------------------------------------------
[2022-01-25 19:25:37,981] {taskinstance.py:1259} INFO - Executing <Task(BashOperator): extract_all_dataa> on 2022-01-25 19:25:35.038530+00:00
[2022-01-25 19:25:37,989] {standard_task_runner.py:52} INFO - Started process 3041 to run task
[2022-01-25 19:25:38,009] {standard_task_runner.py:76} INFO - Running: ['***', 'tasks', 'run', 'ingest_data', 'extract_all_dataa', 'manual__2022-01-25T19:25:35.038530+00:00', '--job-id', '32', '--raw', '--subdir', 'DAGS_FOLDER/dag_01.py', '--cfg-path', '/tmp/tmptex6upmg', '--error-file', '/tmp/tmpnjilon2p']
[2022-01-25 19:25:38,011] {standard_task_runner.py:77} INFO - Job 32: Subtask extract_all_dataa
[2022-01-25 19:25:38,181] {logging_mixin.py:109} INFO - Running <TaskInstance: ingest_data.extract_all_dataa manual__2022-01-25T19:25:35.038530+00:00 [running]> on host 223810fcea28
[2022-01-25 19:25:38,349] {taskinstance.py:1426} INFO - Exporting the following env vars:
AIRFLOW_CTX_DAG_OWNER=***
AIRFLOW_CTX_DAG_ID=ingest_data
AIRFLOW_CTX_TASK_ID=extract_all_dataa
AIRFLOW_CTX_EXECUTION_DATE=2022-01-25T19:25:35.038530+00:00
AIRFLOW_CTX_DAG_RUN_ID=manual__2022-01-25T19:25:35.038530+00:00
[2022-01-25 19:25:38,351] {subprocess.py:62} INFO - Tmp dir root location: 
 /tmp
[2022-01-25 19:25:38,353] {subprocess.py:74} INFO - Running command: ['bash', '-c', 'python ./functions/extract.py']
[2022-01-25 19:25:38,381] {subprocess.py:85} INFO - Output:
[2022-01-25 19:25:38,651] {subprocess.py:89} INFO - python: can't open file './functions/extract.py': [Errno 2] No such file or directory
[2022-01-25 19:25:38,651] {subprocess.py:93} INFO - Command exited with return code 2
[2022-01-25 19:25:38,670] {taskinstance.py:1700} ERROR - Task failed with exception
Traceback (most recent call last):
  File "/home/airflow/.local/lib/python3.6/site-packages/airflow/models/taskinstance.py", line 1329, in _run_raw_task
    self._execute_task_with_callbacks(context)
  File "/home/airflow/.local/lib/python3.6/site-packages/airflow/models/taskinstance.py", line 1455, in _execute_task_with_callbacks
    result = self._execute_task(context, self.task)
  File "/home/airflow/.local/lib/python3.6/site-packages/airflow/models/taskinstance.py", line 1511, in _execute_task
    result = execute_callable(context=context)
  File "/home/airflow/.local/lib/python3.6/site-packages/airflow/operators/bash.py", line 188, in execute
    f'Bash command failed. The command returned a non-zero exit code {result.exit_code}.'
airflow.exceptions.AirflowException: Bash command failed. The command returned a non-zero exit code 2.
[2022-01-25 19:25:38,680] {taskinstance.py:1277} INFO - Marking task as FAILED. dag_id=ingest_data, task_id=extract_all_dataa, execution_date=20220125T192535, start_date=20220125T192537, end_date=20220125T192538
[2022-01-25 19:25:38,696] {standard_task_runner.py:92} ERROR - Failed to execute job 32 for task extract_all_dataa
Traceback (most recent call last):
  File "/home/airflow/.local/lib/python3.6/site-packages/airflow/task/task_runner/standard_task_runner.py", line 85, in _start_by_fork
    args.func(args, dag=self.dag)
  File "/home/airflow/.local/lib/python3.6/site-packages/airflow/cli/cli_parser.py", line 48, in command
    return func(*args, **kwargs)
  File "/home/airflow/.local/lib/python3.6/site-packages/airflow/utils/cli.py", line 92, in wrapper
    return f(*args, **kwargs)
  File "/home/airflow/.local/lib/python3.6/site-packages/airflow/cli/commands/task_command.py", line 298, in task_run
    _run_task_by_selected_method(args, dag, ti)
  File "/home/airflow/.local/lib/python3.6/site-packages/airflow/cli/commands/task_command.py", line 107, in _run_task_by_selected_method
    _run_raw_task(args, ti)
  File "/home/airflow/.local/lib/python3.6/site-packages/airflow/cli/commands/task_command.py", line 184, in _run_raw_task
    error_file=args.error_file,
  File "/home/airflow/.local/lib/python3.6/site-packages/airflow/utils/session.py", line 70, in wrapper
    return func(*args, session=session, **kwargs)
  File "/home/airflow/.local/lib/python3.6/site-packages/airflow/models/taskinstance.py", line 1329, in _run_raw_task
    self._execute_task_with_callbacks(context)
  File "/home/airflow/.local/lib/python3.6/site-packages/airflow/models/taskinstance.py", line 1455, in _execute_task_with_callbacks
    result = self._execute_task(context, self.task)
  File "/home/airflow/.local/lib/python3.6/site-packages/airflow/models/taskinstance.py", line 1511, in _execute_task
    result = execute_callable(context=context)
  File "/home/airflow/.local/lib/python3.6/site-packages/airflow/operators/bash.py", line 188, in execute
    f'Bash command failed. The command returned a non-zero exit code {result.exit_code}.'
airflow.exceptions.AirflowException: Bash command failed. The command returned a non-zero exit code 2.
[2022-01-25 19:25:38,711] {local_task_job.py:154} INFO - Task exited with return code 1
[2022-01-25 19:25:38,747] {local_task_job.py:264} INFO - 0 downstream tasks scheduled from follow-on schedule check
